Workbook

Sheet Crianças
A1: Nome da criança | B1: Sexo (M/F) | C1: Data de nascimento | D1: Nome do responsável | E1: Telefone do responsável | F1: Congregação | G1: Restrição alimentar | H1: Qual restrição | I1: Autismo | J1: Presenças (jan–jul 2026) | K1: Pendências | L1: Observações
A2: Alessia Alves Barbosa | B2: F | C2: 43865 | D2: Cristiane Alves da Silva | E2: 93145-5868 | F2: Pq. Santa Teresa | J2: 19 | K2: =TRIM(IF(B2="","sexo; ","")&IF(C2="","data de nascimento; ","")&IF(D2="","responsável; ","")&IF(E2="","telefone; ","")&IF(AND(G2="Sim",H2=""),"qual restrição; ",""))
A3: Alice Fernandes | B3: F | D3: Maria de Lourdes | E3: 96512-4742 | J3: 1 | K3: =TRIM(IF(B3="","sexo; ","")&IF(C3="","data de nascimento; ","")&IF(D3="","responsável; ","")&IF(E3="","telefone; ","")&IF(AND(G3="Sim",H3=""),"qual restrição; ","")) -> data de nascimento;
A4: Alice Salvador Elias | B4: F | C4: 42682 | D4: Leana Flavia Salvador Elias | E4: (11) 94862-7384 | F4: Pq. Santa Teresa | J4: 3 | K4: =TRIM(IF(B4="","sexo; ","")&IF(C4="","data de nascimento; ","")&IF(D4="","responsável; ","")&IF(E4="","telefone; ","")&IF(AND(G4="Sim",H4=""),"qual restrição; ",""))
A5: Alicia Costa Faria | B5: F | C5: 41792 | D5: Greice Kely Faria | E5: 94797-3304 | J5: 1 | K5: =TRIM(IF(B5="","sexo; ","")&IF(C5="","data de nascimento; ","")&IF(D5="","responsável; ","")&IF(E5="","telefone; ","")&IF(AND(G5="Sim",H5=""),"qual restrição; ",""))
A6: Alícia Estevo Fernandes | B6: F | C6: 43444 | D6: Milena Cristina Felix | E6: 93451-7932 | J6: 15 | K6: =TRIM(IF(B6="","sexo; ","")&IF(C6="","data de nascimento; ","")&IF(D6="","responsável; ","")&IF(E6="","telefone; ","")&IF(AND(G6="Sim",H6=""),"qual restrição; ",""))
A7: Alicia Gabrielly Verciani de Farias | B7: F | C7: 41684 | D7: Edimara Neves de Faria | E7: 96950-9058 | J7: 1 | K7: =TRIM(IF(B7="","sexo; ","")&IF(C7="","data de nascimento; ","")&IF(D7="","responsável; ","")&IF(E7="","telefone; ","")&IF(AND(G7="Sim",H7=""),"qual restrição; ",""))
A8: Ana Clara Maia | B8: F | C8: 44037 | D8: Neuda Maia | E8: 97345-1615 | F8: Jd. Novo Horizonte 2 | J8: 1 | K8: =TRIM(IF(B8="","sexo; ","")&IF(C8="","data de nascimento; ","")&IF(D8="","responsável; ","")&IF(E8="","telefone; ","")&IF(AND(G8="Sim",H8=""),"qual restrição; ",""))
A9: Ana Júlia do Nascimento Ferreira | B9: F | C9: 41708 | D9: Marisa de Oliveira | E9: 96779-9374 | J9: 9 | K9: =TRIM(IF(B9="","sexo; ","")&IF(C9="","data de nascimento; ","")&IF(D9="","responsável; ","")&IF(E9="","telefone; ","")&IF(AND(G9="Sim",H9=""),"qual restrição; ",""))
A10: Ana Júlia Ferreira Alves | B10: F | C10: 42312 | D10: Rosana Regina Rosa | E10: 9735-6275 | J10: 3 | K10: =TRIM(IF(B10="","sexo; ","")&IF(C10="","data de nascimento; ","")&IF(D10="","responsável; ","")&IF(E10="","telefone; ","")&IF(AND(G10="Sim",H10=""),"qual restrição; ",""))
A11: Antonio Miguel Barranhos | B11: M | D11: Claudia Barranhos | J11: 1 | K11: =TRIM(IF(B11="","sexo; ","")&IF(C11="","data de nascimento; ","")&IF(D11="","responsável; ","")&IF(E11="","telefone; ","")&IF(AND(G11="Sim",H11=""),"qual restrição; ","")) -> data de nascimento; telefone;
A12: Arthur Albino Lima | B12: M | C12: 41753 | D12: Claudia Lima | E12: 9928-9255 | J12: 1 | K12: =TRIM(IF(B12="","sexo; ","")&IF(C12="","data de nascimento; ","")&IF(D12="","responsável; ","")&IF(E12="","telefone; ","")&IF(AND(G12="Sim",H12=""),"qual restrição; ",""))
A13: Arthur Carvalho | B13: M | C13: 42954 | D13: Janario | E13: (11) 97303-2058 | F13: Silviana | J13: 1 | K13: =TRIM(IF(B13="","sexo; ","")&IF(C13="","data de nascimento; ","")&IF(D13="","responsável; ","")&IF(E13="","telefone; ","")&IF(AND(G13="Sim",H13=""),"qual restrição; ",""))
A14: Arthur de Oliviera | B14: M | C14: 43297 | D14: Marco Aurélio de Oliviera | E14: 98790-3950 | J14: 3 | K14: =TRIM(IF(B14="","sexo; ","")&IF(C14="","data de nascimento; ","")&IF(D14="","responsável; ","")&IF(E14="","telefone; ","")&IF(AND(G14="Sim",H14=""),"qual restrição; ",""))
A15: Arthur dos Santos Vieira | B15: M | C15: 43069 | D15: Alice Rodrigues dos Santos Silva | E15: 99103-2515 | J15: 2 | K15: =TRIM(IF(B15="","sexo; ","")&IF(C15="","data de nascimento; ","")&IF(D15="","responsável; ","")&IF(E15="","telefone; ","")&IF(AND(G15="Sim",H15=""),"qual restrição; ",""))
A16: Ayla Galdêncio | B16: F | C16: 43594 | D16: Zenaide Gaudêncio | E16: 95490-7307 | J16: 11 | K16: =TRIM(IF(B16="","sexo; ","")&IF(C16="","data de nascimento; ","")&IF(D16="","responsável; ","")&IF(E16="","telefone; ","")&IF(AND(G16="Sim",H16=""),"qual restrição; ",""))
A17: Beatriz Martins Arruda | B17: F | C17: 44248 | D17: Karina Martins | E17: 97966-4252 | J17: 2 | K17: =TRIM(IF(B17="","sexo; ","")&IF(C17="","data de nascimento; ","")&IF(D17="","responsável; ","")&IF(E17="","telefone; ","")&IF(AND(G17="Sim",H17=""),"qual restrição; ",""))
A18: Benjamim Marques | B18: M | C18: 44122 | D18: Sabrina Carnelossi | E18: 98463-7683 | J18: 8 | K18: =TRIM(IF(B18="","sexo; ","")&IF(C18="","data de nascimento; ","")&IF(D18="","responsável; ","")&IF(E18="","telefone; ","")&IF(AND(G18="Sim",H18=""),"qual restrição; ",""))
A19: Bernardo Cerqueira | B19: M | J19: 1 | K19: =TRIM(IF(B19="","sexo; ","")&IF(C19="","data de nascimento; ","")&IF(D19="","responsável; ","")&IF(E19="","telefone; ","")&IF(AND(G19="Sim",H19=""),"qual restrição; ","")) -> data de nascimento; responsável; telefone;
A20: Bernardo Silva Costa Rocha | B20: M | C20: 43588 | D20: Taís Cristina Rocha | E20: (11) 97522-6865 | F20: Pq. Santa Teresa | J20: 5 | K20: =TRIM(IF(B20="","sexo; ","")&IF(C20="","data de nascimento; ","")&IF(D20="","responsável; ","")&IF(E20="","telefone; ","")&IF(AND(G20="Sim",H20=""),"qual restrição; ",""))
A21: Bianca Jeronimo Azevedo | B21: F | C21: 44514 | D21: Sandra Ribeiro | E21: 94088-3095 | J21: 1 | K21: =TRIM(IF(B21="","sexo; ","")&IF(C21="","data de nascimento; ","")&IF(D21="","responsável; ","")&IF(E21="","telefone; ","")&IF(AND(G21="Sim",H21=""),"qual restrição; ",""))
A22: Bryan Anthony Andrade de Deus | B22: M | C22: 41687 | D22: Marilza Alves | F22: Aldeia de Barueri | J22: 1 | K22: =TRIM(IF(B22="","sexo; ","")&IF(C22="","data de nascimento; ","")&IF(D22="","responsável; ","")&IF(E22="","telefone; ","")&IF(AND(G22="Sim",H22=""),"qual restrição; ","")) -> telefone;
A23: Calebe Bernardino Nascimento | B23: M | C23: 44133 | D23: Antônia Elioneide Vieira | E23: 98162-4746 | F23: Pq. Santa Teresa | J23: 6 | K23: =TRIM(IF(B23="","sexo; ","")&IF(C23="","data de nascimento; ","")&IF(D23="","responsável; ","")&IF(E23="","telefone; ","")&IF(AND(G23="Sim",H23=""),"qual restrição; ",""))
A24: Carlos Eduardo | B24: M | D24: Carlos Alberto Dias | E24: (11) 94576-3638 | J24: 1 | K24: =TRIM(IF(B24="","sexo; ","")&IF(C24="","data de nascimento; ","")&IF(D24="","responsável; ","")&IF(E24="","telefone; ","")&IF(AND(G24="Sim",H24=""),"qual restrição; ","")) -> data de nascimento; | L24: Data de nascimento na planilha (24/11/2026) é inválida; deixei em branco.
A25: Daniel Almeida | B25: M | D25: Quezia Perez | E25: 95477-8131 | J25: 1 | K25: =TRIM(IF(B25="","sexo; ","")&IF(C25="","data de nascimento; ","")&IF(D25="","responsável; ","")&IF(E25="","telefone; ","")&IF(AND(G25="Sim",H25=""),"qual restrição; ","")) -> data de nascimento;
A26: Davi Dias | B26: M | D26: Sebastião | E26: (11) 94285-1843 | J26: 1 | K26: =TRIM(IF(B26="","sexo; ","")&IF(C26="","data de nascimento; ","")&IF(D26="","responsável; ","")&IF(E26="","telefone; ","")&IF(AND(G26="Sim",H26=""),"qual restrição; ","")) -> data de nascimento;
A27: Davi Dias Meuquior | B27: M | D27: Carlos Dias Mouquior | E27: (11) 94576-3638 | J27: 1 | K27: =TRIM(IF(B27="","sexo; ","")&IF(C27="","data de nascimento; ","")&IF(D27="","responsável; ","")&IF(E27="","telefone; ","")&IF(AND(G27="Sim",H27=""),"qual restrição; ","")) -> data de nascimento;
A28: Davi Lucas Dasilva Campos | B28: M | D28: Betania Cristina | J28: 1 | K28: =TRIM(IF(B28="","sexo; ","")&IF(C28="","data de nascimento; ","")&IF(D28="","responsável; ","")&IF(E28="","telefone; ","")&IF(AND(G28="Sim",H28=""),"qual restrição; ","")) -> data de nascimento; telefone;
A29: Davi Magalhaes | B29: M | C29: 44941 | D29: Maiara Magalhaes | E29: (11) 98571-6036 | F29: Santa Mariana | J29: 3 | K29: =TRIM(IF(B29="","sexo; ","")&IF(C29="","data de nascimento; ","")&IF(D29="","responsável; ","")&IF(E29="","telefone; ","")&IF(AND(G29="Sim",H29=""),"qual restrição; ",""))
A30: Davi Rodrigues Sabino | B30: M | D30: Paulo Vinicius | J30: 1 | K30: =TRIM(IF(B30="","sexo; ","")&IF(C30="","data de nascimento; ","")&IF(D30="","responsável; ","")&IF(E30="","telefone; ","")&IF(AND(G30="Sim",H30=""),"qual restrição; ","")) -> data de nascimento; telefone;
A31: Davi Sabino de Jesus da Silva | B31: M | C31: 42905 | D31: Manoel Sabino de Jesus da Silva | J31: 1 | K31: =TRIM(IF(B31="","sexo; ","")&IF(C31="","data de nascimento; ","")&IF(D31="","responsável; ","")&IF(E31="","telefone; ","")&IF(AND(G31="Sim",H31=""),"qual restrição; ","")) -> telefone;
A32: Elena Lopes | B32: F | C32: 43881 | D32: Francisca Amorim | E32: 97984-2929 | J32: 16 | K32: =TRIM(IF(B32="","sexo; ","")&IF(C32="","data de nascimento; ","")&IF(D32="","responsável; ","")&IF(E32="","telefone; ","")&IF(AND(G32="Sim",H32=""),"qual restrição; ","")) | L32: Também consta com o responsável Juselino Rodrigues (tel. 9623138).
A33: Emilly Sophia de Souza | B33: F | C33: 42192 | D33: Eliene Pereira | E33: 97674-9894 | J33: 1 | K33: =TRIM(IF(B33="","sexo; ","")&IF(C33="","data de nascimento; ","")&IF(D33="","responsável; ","")&IF(E33="","telefone; ","")&IF(AND(G33="Sim",H33=""),"qual restrição; ",""))
A34: Emily Melo de Oliveira | B34: F | C34: 43218 | D34: Deise Melo | E34: 9759-8735 | J34: 6 | K34: =TRIM(IF(B34="","sexo; ","")&IF(C34="","data de nascimento; ","")&IF(D34="","responsável; ","")&IF(E34="","telefone; ","")&IF(AND(G34="Sim",H34=""),"qual restrição; ",""))
A35: Enrico Barros Freitas | B35: M | C35: 44962 | D35: Diego Freitas | E35: (11) 93143-9971 | J35: 1 | K35: =TRIM(IF(B35="","sexo; ","")&IF(C35="","data de nascimento; ","")&IF(D35="","responsável; ","")&IF(E35="","telefone; ","")&IF(AND(G35="Sim",H35=""),"qual restrição; ",""))
A36: Esther Alves Nunes | B36: F | C36: 43572 | D36: Gilvana Ana | E36: 95050-6690 | J36: 6 | K36: =TRIM(IF(B36="","sexo; ","")&IF(C36="","data de nascimento; ","")&IF(D36="","responsável; ","")&IF(E36="","telefone; ","")&IF(AND(G36="Sim",H36=""),"qual restrição; ","")) | L36: Também consta como "Ester", com responsável Cassiana Alves Nunes (95426-8373).
A37: Fabio Emanuel de Oliveira Neves | B37: M | C37: 42680 | D37: Fabio de Oliveira Neves | E37: (11) 94026-0473 | J37: 9 | K37: =TRIM(IF(B37="","sexo; ","")&IF(C37="","data de nascimento; ","")&IF(D37="","responsável; ","")&IF(E37="","telefone; ","")&IF(AND(G37="Sim",H37=""),"qual restrição; ",""))
A38: Felipe Gabriel Soares Lima | B38: M | C38: 41640 | D38: Maria Daniela Soares Lima | E38: (11) 96561-0103 | F38: Pq. Santa Teresa | I38: Sim | J38: 18 | K38: =TRIM(IF(B38="","sexo; ","")&IF(C38="","data de nascimento; ","")&IF(D38="","responsável; ","")&IF(E38="","telefone; ","")&IF(AND(G38="Sim",H38=""),"qual restrição; ","")) | L38: Marcado como autista na planilha.
A39: Fernanda Mendonça | B39: F | D39: Aline Mendonça | J39: 1 | K39: =TRIM(IF(B39="","sexo; ","")&IF(C39="","data de nascimento; ","")&IF(D39="","responsável; ","")&IF(E39="","telefone; ","")&IF(AND(G39="Sim",H39=""),"qual restrição; ","")) -> data de nascimento; telefone;
A40: Gabriel Bezerra de Almeida | B40: M | C40: 44203 | D40: Alessandra Cristina | E40: 96201-8303 | J40: 3 | K40: =TRIM(IF(B40="","sexo; ","")&IF(C40="","data de nascimento; ","")&IF(D40="","responsável; ","")&IF(E40="","telefone; ","")&IF(AND(G40="Sim",H40=""),"qual restrição; ",""))
...

Sheet Resumo
A1: Resumo da planilha de crianças do EBI
A3: Total de crianças | B3: =COUNTA(Crianças!A2:A140) -> 139
A4: Meninos (M) | B4: =COUNTIF(Crianças!B2:B140,"M") -> 62
A5: Meninas (F) | B5: =COUNTIF(Crianças!B2:B140,"F") -> 77
A6: Com autismo | B6: =COUNTIF(Crianças!I2:I140,"Sim") -> 5
A7: Com restrição alimentar | B7: =COUNTIF(Crianças!G2:G140,"Sim") -> 5
A8: Com congregação informada | B8: =COUNTA(Crianças!F2:F140) -> 26
A9: Sem data de nascimento | B9: =COUNTBLANK(Crianças!C2:C140) -> 28
A10: Sem nome do responsável | B10: =COUNTBLANK(Crianças!D2:D140) -> 6
A11: Sem telefone | B11: =COUNTBLANK(Crianças!E2:E140) -> 26
A12: Crianças com alguma pendência | B12: =COUNTIF(Crianças!K2:K140,"?*") -> 39
A14: Quantas crianças ficam conforme o mínimo de presenças
A15: Mínimo de presenças (edite o número) | B15: Crianças
A16: 1 | B16: =COUNTIF(Crianças!J2:J140,">="&A16) -> 139
A17: 2 | B17: =COUNTIF(Crianças!J2:J140,">="&A17) -> 72
A18: 3 | B18: =COUNTIF(Crianças!J2:J140,">="&A18) -> 53
A19: 4 | B19: =COUNTIF(Crianças!J2:J140,">="&A19) -> 43
A20: 5 | B20: =COUNTIF(Crianças!J2:J140,">="&A20) -> 37
A22: Critério usado: ficaram as crianças com pelo menos 1 presença registrada na planilha (jan a 1º sábado de jul/2026).
A23: As que não tiveram nenhuma presença estão na aba "Retiradas", para você conferir.
A24: De agosto a dezembro a planilha original não tem presenças preenchidas.
A25: Células amarelas na aba "Crianças" = dado obrigatório que falta. Laranja = restrição sem dizer qual.
A26: Restrição alimentar e autismo em branco = nenhuma informação recebida.

Sheet Conferir
A1: A) Nomes que juntei em uma só criança (confirme os de certeza "Média")
A2: Ficou como | B2: Nomes encontrados na planilha | C2: Certeza | D2: Motivo
A3: Alice Salvador Elias | B3: ALICE SALVADOR ELIAS | ALICIA SALVADOR | C3: Média | D3: Nomes parecidos, nunca presentes no mesmo sábado; "Alicia Salvador" estava marcada para completar cadastro.
A4: Arthur dos Santos Vieira | B4: ARTHUR DOS SANTOS | ARTHUR DOS SANTOS VIEIRA | C4: Média | D4: Cadastrado sem dados em abril e com nome completo em junho; sem presença no mesmo sábado.
A5: Beatriz Martins Arruda | B5: BEATRIZ MARTINS ARRUDA | MEATRIZ MARTINS ARRUDA | C5: Alta | D5: "Meatriz" é erro de digitação; mesmo telefone.
A6: Benjamim Marques | B6: BENJAMIM MARQUES | BENNJAMIN MARQUES | C6: Alta | D6: Mesma data de nascimento, responsável e telefone.
A7: Davi Magalhaes | B7: DAVI MAGALHAES | DAVI MAGALHÃES VILAR | C7: Alta | D7: Mesma data de nascimento e telefone.
A8: Elena Lopes | B8: ELENA LOPES | ELENA LOPES BATISTA | HELENA LOPES | C8: Média | D8: Mesma data de nascimento (20/02/2020), mas dois responsáveis: Francisca Amorim e Juselino Rodrigues. Usei Francisca (aparece em todos os meses).
A9: Esther Alves Nunes | B9: ESTER ALVES NUNES | ESTHER ALVES NUNES | C9: Média | D9: Duas linhas quase iguais, com responsáveis e telefones diferentes, nunca presentes no mesmo sábado. Usei a linha com data de nascimento.
A10: Felipe Gabriel Soares Lima | B10: FELIPE GABRIEL SOARES | FELIPE GABRIEL SOARES LIMA | C10: Alta | D10: Linha sem sobrenome e sem dados.
A11: Gael da Rocha Oliviera | B11: GAEL DA ROCHA OLIVIERA | GAEL DA ROCJHA OLIVIERA | C11: Alta | D11: Erro de digitação; mesma data de nascimento e responsável.
A12: Geovanna Coelho da Silva | B12: GEOVANNA COELHO DA SILVA | GIOVANNA COELHO DA SILVA | C12: Alta | D12: Mesma data de nascimento, responsável e telefone.
A13: Isabela Olimpio | B13: ISABELA OLIMPIO | ISABELLA OLIMPIO | C13: Alta | D13: Mesmo responsável (Aline).
... A20: Rian Meireles Oliveira | B20: RIAN MEIRELES OLIVEIRA | RIAN MEIRELES OLIVVEIRA | RYAN MEIRELES OLIVVEIRA | C20: Alta | D20: Erro de digitação; mesma data de nascimento, responsável e telefone.
A22: B) Nomes parecidos que mantive SEPARADOS (confirme se são a mesma criança)
A23: Criança 1 | B23: Criança 2 | D23: Por que fiquei em dúvida
A24: Davi Dias (resp. Sebastião) | B24: Davi Dias Meuquior (resp. Carlos Dias Mouquior) | D24: Sobrenome parecido, mas responsáveis e telefones diferentes.
A25: Davi Rodrigues Sabino (resp. Paulo Vinicius) | B25: Davi Sabino de Jesus da Silva (resp. Manoel Sabino) | D25: Sobrenome Sabino em comum; responsáveis diferentes.
A26: Miguel Brito (resp. Graziela Silva Brito) | B26: Miguel Ramos Leme | D26: Mesma responsável em algumas linhas, mas datas de nascimento diferentes (2018 e 2016).
A27: Maitê (resp. Maria de Luz) | B27: Maitê Magalhães / Maitê Magalhães Oliveira | D27: Três registros com nome parecido; tiveram presença no mesmo sábado, então mantive separados.
A28: Maria Vitória de Oliveira | B28: Maria Vitória Oliveira | D28: Nomes quase iguais, mas datas de nascimento e responsáveis diferentes.
A29: Bernardo Cerqueira | B29: Bernardo Silva Costa Rocha | D29: Mesmo primeiro nome; sem dados para comparar.
A31: C) Dados estranhos ou faltando na planilha original
A32: Assunto | B32: O que encontrei | D32: O que fiz
A33: Criança sem nome (aba Maio, linha 282) | B33: A célula do nome só tem "1". Sexo F, nascimento 06/03/2017, responsável Iraci Alves de Carvalho, 1 presença. | D33: Não entrou na lista principal. Se você souber o nome, é só me dizer que eu incluo.
A34: Carlos Eduardo | B34: Data de nascimento 24/11/2026 (no futuro). | D34: Deixei a data em branco.
A35: Júlia Brizzola | B35: Sexo M na planilha, mas o nome é feminino. | D35: Mantive M como estava; confirme.
A36: Felipe Gabriel Soares Lima e Roger Roberto Gomes de Melo | B36: Nascimento 01/01/2014 e 01/01/2015: parecem datas provisórias. | D36: Mantive como estava.
A37: Isaque da irmã Débora | B37: Não há "Isaque" com responsável Débora; o mais provável é Isaac Pinheiro dos Santos (mãe Débora Antunes Pinheiro dos Santos). | D37: Marquei autismo nele. Confirme se é este.
A38: Laura Valentina Rodrigues Sales | B38: A aba Abril indica autismo, mas ela não tem nenhuma presença registrada. | D38: Ficou na aba "Retiradas".
A39: Rafaela de Oliveira Chaves | B39: Você informou restrição alimentar, mas não sei qual. | D39: Deixei "Qual restrição" em branco (célula laranja).

Sheet Retiradas
A1: Nome da criança | B1: Sexo | C1: Nome do responsável | D1: Telefone | E1: Presenças | F1: Observação
A2: Agatha Marques | B2: F | C2: Ana Paula | E2: 0
A3: Agnes Bulhoes | B3: F | C3: Geilza Bulhoes | D3: 96210-6191 | E3: 0
A4: Alice Liane O. Lenke | B4: F | C4: Mariana D. Osório | D4: 98315-9041 | E4: 0
A5: Alicia Zahir Santana | B5: F | C5: Simone Araujo | D5: 98115-6307 | E5: 0
A6: Alisson de Jesus Santos | B6: M | D6: 11966-5318 | E6: 0
A7: Amabil Habasa | B7: F | C7: Edson Moises Alves | D7: (94) 6557-5722 | E7: 0
A8: Ana Carolyne Almeida Lima | B8: F | C8: Ir. Débora Pereira | D8: 99516-0118 | E8: 0
A9: Ana Clara | B9: F | C9: Marta Magalhães | D9: (11) 99587-4751 | E9: 0
A10: Ana Clara Cardosa da Silva | B10: F | C10: Maria Salvani | E10: 0
A11: Ana Clara da Silva Ribeiro | B11: F | C11: Jaqueline Alves da Silva Ribeiro | D11: (11) 94725-9974 | E11: 0
A12: Ana Clara Gonçalves de Alencar | B12: F | C12: Marta Magalhães | D12: (11) 99587-4751 | E12: 0
A13: Ana Flavia | B13: F | C13: Patricia Regina | D13: 94435-0636 | E13: 0
A14: Ana Flavia Oliveira Pires | B14: F | C14: Daniele de Freitas Santos | D14: 98449-8852 | E14: 0
A15: Ana Vitoria Oliveira Santos | B15: F | C15: Ana Vitória Oliveira | D15: (11) 95649-5684 | E15: 0
A16: Anthoni Gabriel Passos | B16: M | C16: Barbara Luana | D16: (73) 99920-4642 | E16: 0
A17: Arthur Coelho Ponte | B17: M | C17: Ágatha Cristie | D17: 96919-3489 | E17: 0
A18: Arthur Luis Alexandre Estevo | B18: M | C18: Milena Estevo | D18: (11) 93451-7933 | E18: 0
A19: Beatriz Manuela Valentim Lourenço | B19: F | C19: Rosangela Valentim | D19: 94329-7076 | E19: 0
A20: Bernardo Leite Luciano | B20: M | C20: Patricia Leite | E20: 0
A21: Breno Gael Silva | B21: M | C21: Celia Silva | D21: (11) 98681-3733 | E21: 0
A22: Bryan da Silva Oliveira | B22: M | C22: Jessica Naiara | D22: 99301-5716 | E22: 0
A23: Catarina Fernandes Maques | B23: F | C23: Dorvalino Marques de Oliveira | D23: (11) 98685-3977 | E23: 0
A24: Clarice Benassi Laurino | B24: F | C24: Ana Paula Benassi Rodrigues | D24: (91) 7641-3558 | E24: 0
A25: Daniel da Silva Lopes | B25: M | C25: Edilaine da Silva Lopes | D25: (96) 2475-3776 | E25: 0
A26: Daniel Gade Pessoa Rodrigues | B26: M | C26: Geane Pessoa | D26: (11) 94532-1151 | E26: 0
A27: Daniel Rodrigues | B27: M | C27: Josilene Mendes Rodrigues | D27: (11) 96403-3898 | E27: 0
A28: Daniel Rodrigues Miguel de Oliveira | B28: M | C28: Karoline Rodrigues Oliveira | D28: (11) 95882-2694 | E28: 0
A29: Daniel Silva Barros | B29: M | C29: Edilaine da Silva Lopes | D29: (96) 2475-3776 | E29: 0
A30: Danielle Eduarda G dos Santos | B30: F | C30: Josiele Gomes | D30: 96084-6647 | E30: 0
A31: Danielle Valentina de Bastos Vieira | B31: F | C31: Deise Aparecida Vieira | D31: 97017-6166 | E31: 0
A32: Davi Arthur B | B32: M | C32: Greyce | D32: 9992-3578 | E32: 0
... A45: Eduardo Damas | B45: M | C45: Dalva Damas | D45: (13) 99744-1541 | E45: 0
A46: Eloa Cardoso | B46: F | C46: Maria Salvani | E46: 0
A47: Emanuelle Oliveira Nunes de Almeida | B47: F | C47: Amanda Almeida | D47: 93408-6727 | E47: 0
A48: Emanuelly de Oliveira Viera | B48: F | C48: Joyce | E48: 0
A49: Emilly Sofia Alves Paixão | B49: F | C49: Kelly Alves Rita | D49: 97645-2712 | E49: 0
A50: Emily Vitoria Marcela de Souza | B50: F | C50: Michele Vanessa Felix Estevo Barcelos | D50: (11) 98766-4940 | E50: 0
A51: Enzo Phelipe Gomes da Silva | B51: M | C51: Greyce Karen da Silva | E51: 0
A52: Ester Ferreira de Lima Moreira | B52: F | E52: 0
...
